2025-08-15 10:46:51,509 [ERROR] Error loading plot 3:
Traceback (most recent call last):
  File "C:\3D_printer\Novel-Cyber-Infrastructure-Enabling-AI-Driven-Analytics-and-Digital-Twins-for-Real-Time-3D-Printing\inferece_deployement\stream1.py", line 127, in load_plot_image
    return Image.open(PLOT_PATHS[index])
           ~~~~~~~~~~^^^^^^^^^^^^^^^^^^^
  File "C:\3D_printer\Novel-Cyber-Infrastructure-Enabling-AI-Driven-Analytics-and-Digital-Twins-for-Real-Time-3D-Printing\venv\Lib\site-packages\PIL\Image.py", line 3580, in open
    raise UnidentifiedImageError(msg)
PIL.UnidentifiedImageError: cannot identify image file 'database\\static\\plot3.png'
2025-08-15 10:46:51,509 [ERROR] Error loading plot 3:
Traceback (most recent call last):
  File "C:\3D_printer\Novel-Cyber-Infrastructure-Enabling-AI-Driven-Analytics-and-Digital-Twins-for-Real-Time-3D-Printing\inferece_deployement\stream1.py", line 127, in load_plot_image
    return Image.open(PLOT_PATHS[index])
           ~~~~~~~~~~^^^^^^^^^^^^^^^^^^^
  File "C:\3D_printer\Novel-Cyber-Infrastructure-Enabling-AI-Driven-Analytics-and-Digital-Twins-for-Real-Time-3D-Printing\venv\Lib\site-packages\PIL\Image.py", line 3580, in open
    raise UnidentifiedImageError(msg)
PIL.UnidentifiedImageError: cannot identify image file 'database\\static\\plot3.png'
2025-08-15 10:46:51,510 [ERROR] Error loading plot 3:
Traceback (most recent call last):
  File "C:\3D_printer\Novel-Cyber-Infrastructure-Enabling-AI-Driven-Analytics-and-Digital-Twins-for-Real-Time-3D-Printing\inferece_deployement\stream1.py", line 127, in load_plot_image
    return Image.open(PLOT_PATHS[index])
           ~~~~~~~~~~^^^^^^^^^^^^^^^^^^^
  File "C:\3D_printer\Novel-Cyber-Infrastructure-Enabling-AI-Driven-Analytics-and-Digital-Twins-for-Real-Time-3D-Printing\venv\Lib\site-packages\PIL\Image.py", line 3580, in open
    raise UnidentifiedImageError(msg)
PIL.UnidentifiedImageError: cannot identify image file 'database\\static\\plot3.png'
2025-08-15 10:46:56,684 [ERROR] Error loading plot 3:
Traceback (most recent call last):
  File "C:\3D_printer\Novel-Cyber-Infrastructure-Enabling-AI-Driven-Analytics-and-Digital-Twins-for-Real-Time-3D-Printing\inferece_deployement\stream1.py", line 127, in load_plot_image
    return Image.open(PLOT_PATHS[index])
           ~~~~~~~~~~^^^^^^^^^^^^^^^^^^^
  File "C:\3D_printer\Novel-Cyber-Infrastructure-Enabling-AI-Driven-Analytics-and-Digital-Twins-for-Real-Time-3D-Printing\venv\Lib\site-packages\PIL\Image.py", line 3580, in open
    raise UnidentifiedImageError(msg)
PIL.UnidentifiedImageError: cannot identify image file 'database\\static\\plot3.png'
2025-08-15 10:46:56,754 [ERROR] Error loading plot 3:
Traceback (most recent call last):
  File "C:\3D_printer\Novel-Cyber-Infrastructure-Enabling-AI-Driven-Analytics-and-Digital-Twins-for-Real-Time-3D-Printing\inferece_deployement\stream1.py", line 127, in load_plot_image
    return Image.open(PLOT_PATHS[index])
           ~~~~~~~~~~^^^^^^^^^^^^^^^^^^^
  File "C:\3D_printer\Novel-Cyber-Infrastructure-Enabling-AI-Driven-Analytics-and-Digital-Twins-for-Real-Time-3D-Printing\venv\Lib\site-packages\PIL\Image.py", line 3580, in open
    raise UnidentifiedImageError(msg)
PIL.UnidentifiedImageError: cannot identify image file 'database\\static\\plot3.png'
2025-08-15 10:46:56,772 [ERROR] Error loading plot 3:
Traceback (most recent call last):
  File "C:\3D_printer\Novel-Cyber-Infrastructure-Enabling-AI-Driven-Analytics-and-Digital-Twins-for-Real-Time-3D-Printing\inferece_deployement\stream1.py", line 127, in load_plot_image
    return Image.open(PLOT_PATHS[index])
           ~~~~~~~~~~^^^^^^^^^^^^^^^^^^^
  File "C:\3D_printer\Novel-Cyber-Infrastructure-Enabling-AI-Driven-Analytics-and-Digital-Twins-for-Real-Time-3D-Printing\venv\Lib\site-packages\PIL\Image.py", line 3580, in open
    raise UnidentifiedImageError(msg)
PIL.UnidentifiedImageError: cannot identify image file 'database\\static\\plot3.png'
2025-08-15 10:47:01,993 [ERROR] Error loading plot 3:
Traceback (most recent call last):
  File "C:\3D_printer\Novel-Cyber-Infrastructure-Enabling-AI-Driven-Analytics-and-Digital-Twins-for-Real-Time-3D-Printing\inferece_deployement\stream1.py", line 127, in load_plot_image
    return Image.open(PLOT_PATHS[index])
           ~~~~~~~~~~^^^^^^^^^^^^^^^^^^^
  File "C:\3D_printer\Novel-Cyber-Infrastructure-Enabling-AI-Driven-Analytics-and-Digital-Twins-for-Real-Time-3D-Printing\venv\Lib\site-packages\PIL\Image.py", line 3580, in open
    raise UnidentifiedImageError(msg)
PIL.UnidentifiedImageError: cannot identify image file 'database\\static\\plot3.png'
2025-08-15 10:47:07,094 [ERROR] Error loading plot 3:
Traceback (most recent call last):
  File "C:\3D_printer\Novel-Cyber-Infrastructure-Enabling-AI-Driven-Analytics-and-Digital-Twins-for-Real-Time-3D-Printing\inferece_deployement\stream1.py", line 127, in load_plot_image
    return Image.open(PLOT_PATHS[index])
           ~~~~~~~~~~^^^^^^^^^^^^^^^^^^^
  File "C:\3D_printer\Novel-Cyber-Infrastructure-Enabling-AI-Driven-Analytics-and-Digital-Twins-for-Real-Time-3D-Printing\venv\Lib\site-packages\PIL\Image.py", line 3580, in open
    raise UnidentifiedImageError(msg)
PIL.UnidentifiedImageError: cannot identify image file 'database\\static\\plot3.png'
2025-08-15 10:47:12,323 [ERROR] Error loading plot 3:
Traceback (most recent call last):
  File "C:\3D_printer\Novel-Cyber-Infrastructure-Enabling-AI-Driven-Analytics-and-Digital-Twins-for-Real-Time-3D-Printing\inferece_deployement\stream1.py", line 127, in load_plot_image
    return Image.open(PLOT_PATHS[index])
           ~~~~~~~~~~^^^^^^^^^^^^^^^^^^^
  File "C:\3D_printer\Novel-Cyber-Infrastructure-Enabling-AI-Driven-Analytics-and-Digital-Twins-for-Real-Time-3D-Printing\venv\Lib\site-packages\PIL\Image.py", line 3580, in open
    raise UnidentifiedImageError(msg)
PIL.UnidentifiedImageError: cannot identify image file 'database\\static\\plot3.png'
2025-08-15 10:47:17,450 [ERROR] Error loading plot 3:
Traceback (most recent call last):
  File "C:\3D_printer\Novel-Cyber-Infrastructure-Enabling-AI-Driven-Analytics-and-Digital-Twins-for-Real-Time-3D-Printing\inferece_deployement\stream1.py", line 127, in load_plot_image
    return Image.open(PLOT_PATHS[index])
           ~~~~~~~~~~^^^^^^^^^^^^^^^^^^^
  File "C:\3D_printer\Novel-Cyber-Infrastructure-Enabling-AI-Driven-Analytics-and-Digital-Twins-for-Real-Time-3D-Printing\venv\Lib\site-packages\PIL\Image.py", line 3580, in open
    raise UnidentifiedImageError(msg)
PIL.UnidentifiedImageError: cannot identify image file 'database\\static\\plot3.png'
2025-08-15 10:47:17,702 [ERROR] Error loading plot 3:
Traceback (most recent call last):
  File "C:\3D_printer\Novel-Cyber-Infrastructure-Enabling-AI-Driven-Analytics-and-Digital-Twins-for-Real-Time-3D-Printing\inferece_deployement\stream1.py", line 127, in load_plot_image
    return Image.open(PLOT_PATHS[index])
           ~~~~~~~~~~^^^^^^^^^^^^^^^^^^^
  File "C:\3D_printer\Novel-Cyber-Infrastructure-Enabling-AI-Driven-Analytics-and-Digital-Twins-for-Real-Time-3D-Printing\venv\Lib\site-packages\PIL\Image.py", line 3580, in open
    raise UnidentifiedImageError(msg)
PIL.UnidentifiedImageError: cannot identify image file 'database\\static\\plot3.png'
2025-08-15 10:47:17,739 [ERROR] Error loading plot 3:
Traceback (most recent call last):
  File "C:\3D_printer\Novel-Cyber-Infrastructure-Enabling-AI-Driven-Analytics-and-Digital-Twins-for-Real-Time-3D-Printing\inferece_deployement\stream1.py", line 127, in load_plot_image
    return Image.open(PLOT_PATHS[index])
           ~~~~~~~~~~^^^^^^^^^^^^^^^^^^^
  File "C:\3D_printer\Novel-Cyber-Infrastructure-Enabling-AI-Driven-Analytics-and-Digital-Twins-for-Real-Time-3D-Printing\venv\Lib\site-packages\PIL\Image.py", line 3580, in open
    raise UnidentifiedImageError(msg)
PIL.UnidentifiedImageError: cannot identify image file 'database\\static\\plot3.png'
2025-08-15 10:47:17,749 [ERROR] Error loading plot 3:
Traceback (most recent call last):
  File "C:\3D_printer\Novel-Cyber-Infrastructure-Enabling-AI-Driven-Analytics-and-Digital-Twins-for-Real-Time-3D-Printing\inferece_deployement\stream1.py", line 127, in load_plot_image
    return Image.open(PLOT_PATHS[index])
           ~~~~~~~~~~^^^^^^^^^^^^^^^^^^^
  File "C:\3D_printer\Novel-Cyber-Infrastructure-Enabling-AI-Driven-Analytics-and-Digital-Twins-for-Real-Time-3D-Printing\venv\Lib\site-packages\PIL\Image.py", line 3580, in open
    raise UnidentifiedImageError(msg)
PIL.UnidentifiedImageError: cannot identify image file 'database\\static\\plot3.png'
2025-08-15 10:47:22,865 [ERROR] Error loading plot 3:
Traceback (most recent call last):
  File "C:\3D_printer\Novel-Cyber-Infrastructure-Enabling-AI-Driven-Analytics-and-Digital-Twins-for-Real-Time-3D-Printing\inferece_deployement\stream1.py", line 127, in load_plot_image
    return Image.open(PLOT_PATHS[index])
           ~~~~~~~~~~^^^^^^^^^^^^^^^^^^^
  File "C:\3D_printer\Novel-Cyber-Infrastructure-Enabling-AI-Driven-Analytics-and-Digital-Twins-for-Real-Time-3D-Printing\venv\Lib\site-packages\PIL\Image.py", line 3580, in open
    raise UnidentifiedImageError(msg)
PIL.UnidentifiedImageError: cannot identify image file 'database\\static\\plot3.png'
2025-08-15 10:47:22,893 [ERROR] Error loading plot 3:
Traceback (most recent call last):
  File "C:\3D_printer\Novel-Cyber-Infrastructure-Enabling-AI-Driven-Analytics-and-Digital-Twins-for-Real-Time-3D-Printing\inferece_deployement\stream1.py", line 127, in load_plot_image
    return Image.open(PLOT_PATHS[index])
           ~~~~~~~~~~^^^^^^^^^^^^^^^^^^^
  File "C:\3D_printer\Novel-Cyber-Infrastructure-Enabling-AI-Driven-Analytics-and-Digital-Twins-for-Real-Time-3D-Printing\venv\Lib\site-packages\PIL\Image.py", line 3580, in open
    raise UnidentifiedImageError(msg)
PIL.UnidentifiedImageError: cannot identify image file 'database\\static\\plot3.png'
2025-08-15 10:47:22,949 [ERROR] Error loading plot 3:
Traceback (most recent call last):
  File "C:\3D_printer\Novel-Cyber-Infrastructure-Enabling-AI-Driven-Analytics-and-Digital-Twins-for-Real-Time-3D-Printing\inferece_deployement\stream1.py", line 127, in load_plot_image
    return Image.open(PLOT_PATHS[index])
           ~~~~~~~~~~^^^^^^^^^^^^^^^^^^^
  File "C:\3D_printer\Novel-Cyber-Infrastructure-Enabling-AI-Driven-Analytics-and-Digital-Twins-for-Real-Time-3D-Printing\venv\Lib\site-packages\PIL\Image.py", line 3580, in open
    raise UnidentifiedImageError(msg)
PIL.UnidentifiedImageError: cannot identify image file 'database\\static\\plot3.png'
2025-08-15 10:47:28,062 [ERROR] Error loading plot 3:
Traceback (most recent call last):
  File "C:\3D_printer\Novel-Cyber-Infrastructure-Enabling-AI-Driven-Analytics-and-Digital-Twins-for-Real-Time-3D-Printing\inferece_deployement\stream1.py", line 127, in load_plot_image
    return Image.open(PLOT_PATHS[index])
           ~~~~~~~~~~^^^^^^^^^^^^^^^^^^^
  File "C:\3D_printer\Novel-Cyber-Infrastructure-Enabling-AI-Driven-Analytics-and-Digital-Twins-for-Real-Time-3D-Printing\venv\Lib\site-packages\PIL\Image.py", line 3580, in open
    raise UnidentifiedImageError(msg)
PIL.UnidentifiedImageError: cannot identify image file 'database\\static\\plot3.png'
2025-08-15 10:47:28,168 [ERROR] Error loading plot 3:
Traceback (most recent call last):
  File "C:\3D_printer\Novel-Cyber-Infrastructure-Enabling-AI-Driven-Analytics-and-Digital-Twins-for-Real-Time-3D-Printing\inferece_deployement\stream1.py", line 127, in load_plot_image
    return Image.open(PLOT_PATHS[index])
           ~~~~~~~~~~^^^^^^^^^^^^^^^^^^^
  File "C:\3D_printer\Novel-Cyber-Infrastructure-Enabling-AI-Driven-Analytics-and-Digital-Twins-for-Real-Time-3D-Printing\venv\Lib\site-packages\PIL\Image.py", line 3580, in open
    raise UnidentifiedImageError(msg)
PIL.UnidentifiedImageError: cannot identify image file 'database\\static\\plot3.png'
2025-08-15 10:47:28,390 [ERROR] Error loading plot 3:
Traceback (most recent call last):
  File "C:\3D_printer\Novel-Cyber-Infrastructure-Enabling-AI-Driven-Analytics-and-Digital-Twins-for-Real-Time-3D-Printing\inferece_deployement\stream1.py", line 127, in load_plot_image
    return Image.open(PLOT_PATHS[index])
           ~~~~~~~~~~^^^^^^^^^^^^^^^^^^^
  File "C:\3D_printer\Novel-Cyber-Infrastructure-Enabling-AI-Driven-Analytics-and-Digital-Twins-for-Real-Time-3D-Printing\venv\Lib\site-packages\PIL\Image.py", line 3580, in open
    raise UnidentifiedImageError(msg)
PIL.UnidentifiedImageError: cannot identify image file 'database\\static\\plot3.png'
2025-08-15 10:56:23,186 [ERROR] Error loading plot 3:
Traceback (most recent call last):
  File "C:\3D_printer\Novel-Cyber-Infrastructure-Enabling-AI-Driven-Analytics-and-Digital-Twins-for-Real-Time-3D-Printing\inferece_deployement\stream1.py", line 127, in load_plot_image
    return Image.open(PLOT_PATHS[index])
           ~~~~~~~~~~^^^^^^^^^^^^^^^^^^^
  File "C:\3D_printer\Novel-Cyber-Infrastructure-Enabling-AI-Driven-Analytics-and-Digital-Twins-for-Real-Time-3D-Printing\venv\Lib\site-packages\PIL\Image.py", line 3580, in open
    raise UnidentifiedImageError(msg)
PIL.UnidentifiedImageError: cannot identify image file 'database\\static\\plot3.png'
2025-08-15 10:56:28,463 [ERROR] Error loading plot 3:
Traceback (most recent call last):
  File "C:\3D_printer\Novel-Cyber-Infrastructure-Enabling-AI-Driven-Analytics-and-Digital-Twins-for-Real-Time-3D-Printing\inferece_deployement\stream1.py", line 127, in load_plot_image
    return Image.open(PLOT_PATHS[index])
           ~~~~~~~~~~^^^^^^^^^^^^^^^^^^^
  File "C:\3D_printer\Novel-Cyber-Infrastructure-Enabling-AI-Driven-Analytics-and-Digital-Twins-for-Real-Time-3D-Printing\venv\Lib\site-packages\PIL\Image.py", line 3580, in open
    raise UnidentifiedImageError(msg)
PIL.UnidentifiedImageError: cannot identify image file 'database\\static\\plot3.png'
2025-08-15 10:56:33,839 [ERROR] Error loading plot 3:
Traceback (most recent call last):
  File "C:\3D_printer\Novel-Cyber-Infrastructure-Enabling-AI-Driven-Analytics-and-Digital-Twins-for-Real-Time-3D-Printing\inferece_deployement\stream1.py", line 127, in load_plot_image
    return Image.open(PLOT_PATHS[index])
           ~~~~~~~~~~^^^^^^^^^^^^^^^^^^^
  File "C:\3D_printer\Novel-Cyber-Infrastructure-Enabling-AI-Driven-Analytics-and-Digital-Twins-for-Real-Time-3D-Printing\venv\Lib\site-packages\PIL\Image.py", line 3580, in open
    raise UnidentifiedImageError(msg)
PIL.UnidentifiedImageError: cannot identify image file 'database\\static\\plot3.png'
2025-08-15 11:10:13,911 [INFO] Command 'start' sent. Status: 204
2025-08-15 11:10:18,244 [ERROR] Error loading plot 3:
Traceback (most recent call last):
  File "C:\3D_printer\Novel-Cyber-Infrastructure-Enabling-AI-Driven-Analytics-and-Digital-Twins-for-Real-Time-3D-Printing\inferece_deployement\stream1.py", line 127, in load_plot_image
    return Image.open(PLOT_PATHS[index])
           ~~~~~~~~~~^^^^^^^^^^^^^^^^^^^
  File "C:\3D_printer\Novel-Cyber-Infrastructure-Enabling-AI-Driven-Analytics-and-Digital-Twins-for-Real-Time-3D-Printing\venv\Lib\site-packages\PIL\Image.py", line 3580, in open
    raise UnidentifiedImageError(msg)
PIL.UnidentifiedImageError: cannot identify image file 'database\\static\\plot3.png'
2025-08-15 11:10:18,652 [ERROR] Error loading plot 3:
Traceback (most recent call last):
  File "C:\3D_printer\Novel-Cyber-Infrastructure-Enabling-AI-Driven-Analytics-and-Digital-Twins-for-Real-Time-3D-Printing\inferece_deployement\stream1.py", line 127, in load_plot_image
    return Image.open(PLOT_PATHS[index])
           ~~~~~~~~~~^^^^^^^^^^^^^^^^^^^
  File "C:\3D_printer\Novel-Cyber-Infrastructure-Enabling-AI-Driven-Analytics-and-Digital-Twins-for-Real-Time-3D-Printing\venv\Lib\site-packages\PIL\Image.py", line 3580, in open
    raise UnidentifiedImageError(msg)
PIL.UnidentifiedImageError: cannot identify image file 'database\\static\\plot3.png'
2025-08-15 11:10:23,362 [ERROR] Error loading plot 3:
Traceback (most recent call last):
  File "C:\3D_printer\Novel-Cyber-Infrastructure-Enabling-AI-Driven-Analytics-and-Digital-Twins-for-Real-Time-3D-Printing\inferece_deployement\stream1.py", line 127, in load_plot_image
    return Image.open(PLOT_PATHS[index])
           ~~~~~~~~~~^^^^^^^^^^^^^^^^^^^
  File "C:\3D_printer\Novel-Cyber-Infrastructure-Enabling-AI-Driven-Analytics-and-Digital-Twins-for-Real-Time-3D-Printing\venv\Lib\site-packages\PIL\Image.py", line 3580, in open
    raise UnidentifiedImageError(msg)
PIL.UnidentifiedImageError: cannot identify image file 'database\\static\\plot3.png'
2025-08-15 11:10:23,651 [ERROR] Error loading plot 3:
Traceback (most recent call last):
  File "C:\3D_printer\Novel-Cyber-Infrastructure-Enabling-AI-Driven-Analytics-and-Digital-Twins-for-Real-Time-3D-Printing\inferece_deployement\stream1.py", line 127, in load_plot_image
    return Image.open(PLOT_PATHS[index])
           ~~~~~~~~~~^^^^^^^^^^^^^^^^^^^
  File "C:\3D_printer\Novel-Cyber-Infrastructure-Enabling-AI-Driven-Analytics-and-Digital-Twins-for-Real-Time-3D-Printing\venv\Lib\site-packages\PIL\Image.py", line 3580, in open
    raise UnidentifiedImageError(msg)
PIL.UnidentifiedImageError: cannot identify image file 'database\\static\\plot3.png'
2025-08-15 11:10:23,903 [ERROR] Error loading plot 3:
Traceback (most recent call last):
  File "C:\3D_printer\Novel-Cyber-Infrastructure-Enabling-AI-Driven-Analytics-and-Digital-Twins-for-Real-Time-3D-Printing\inferece_deployement\stream1.py", line 127, in load_plot_image
    return Image.open(PLOT_PATHS[index])
           ~~~~~~~~~~^^^^^^^^^^^^^^^^^^^
  File "C:\3D_printer\Novel-Cyber-Infrastructure-Enabling-AI-Driven-Analytics-and-Digital-Twins-for-Real-Time-3D-Printing\venv\Lib\site-packages\PIL\Image.py", line 3580, in open
    raise UnidentifiedImageError(msg)
PIL.UnidentifiedImageError: cannot identify image file 'database\\static\\plot3.png'
2025-08-15 11:10:28,640 [ERROR] Error loading plot 2:
Traceback (most recent call last):
  File "C:\3D_printer\Novel-Cyber-Infrastructure-Enabling-AI-Driven-Analytics-and-Digital-Twins-for-Real-Time-3D-Printing\inferece_deployement\stream1.py", line 127, in load_plot_image
    return Image.open(PLOT_PATHS[index])
           ~~~~~~~~~~^^^^^^^^^^^^^^^^^^^
  File "C:\3D_printer\Novel-Cyber-Infrastructure-Enabling-AI-Driven-Analytics-and-Digital-Twins-for-Real-Time-3D-Printing\venv\Lib\site-packages\PIL\Image.py", line 3580, in open
    raise UnidentifiedImageError(msg)
PIL.UnidentifiedImageError: cannot identify image file 'database\\static\\plot2.png'
2025-08-15 11:10:28,643 [ERROR] Error loading plot 3:
Traceback (most recent call last):
  File "C:\3D_printer\Novel-Cyber-Infrastructure-Enabling-AI-Driven-Analytics-and-Digital-Twins-for-Real-Time-3D-Printing\inferece_deployement\stream1.py", line 127, in load_plot_image
    return Image.open(PLOT_PATHS[index])
           ~~~~~~~~~~^^^^^^^^^^^^^^^^^^^
  File "C:\3D_printer\Novel-Cyber-Infrastructure-Enabling-AI-Driven-Analytics-and-Digital-Twins-for-Real-Time-3D-Printing\venv\Lib\site-packages\PIL\Image.py", line 3580, in open
    raise UnidentifiedImageError(msg)
PIL.UnidentifiedImageError: cannot identify image file 'database\\static\\plot3.png'
2025-08-15 11:10:29,247 [ERROR] Error loading plot 3:
Traceback (most recent call last):
  File "C:\3D_printer\Novel-Cyber-Infrastructure-Enabling-AI-Driven-Analytics-and-Digital-Twins-for-Real-Time-3D-Printing\inferece_deployement\stream1.py", line 127, in load_plot_image
    return Image.open(PLOT_PATHS[index])
           ~~~~~~~~~~^^^^^^^^^^^^^^^^^^^
  File "C:\3D_printer\Novel-Cyber-Infrastructure-Enabling-AI-Driven-Analytics-and-Digital-Twins-for-Real-Time-3D-Printing\venv\Lib\site-packages\PIL\Image.py", line 3580, in open
    raise UnidentifiedImageError(msg)
PIL.UnidentifiedImageError: cannot identify image file 'database\\static\\plot3.png'
2025-08-15 11:10:33,999 [ERROR] Error loading plot 3:
Traceback (most recent call last):
  File "C:\3D_printer\Novel-Cyber-Infrastructure-Enabling-AI-Driven-Analytics-and-Digital-Twins-for-Real-Time-3D-Printing\inferece_deployement\stream1.py", line 127, in load_plot_image
    return Image.open(PLOT_PATHS[index])
           ~~~~~~~~~~^^^^^^^^^^^^^^^^^^^
  File "C:\3D_printer\Novel-Cyber-Infrastructure-Enabling-AI-Driven-Analytics-and-Digital-Twins-for-Real-Time-3D-Printing\venv\Lib\site-packages\PIL\Image.py", line 3580, in open
    raise UnidentifiedImageError(msg)
PIL.UnidentifiedImageError: cannot identify image file 'database\\static\\plot3.png'
2025-08-15 11:10:34,602 [ERROR] Error loading plot 3:
Traceback (most recent call last):
  File "C:\3D_printer\Novel-Cyber-Infrastructure-Enabling-AI-Driven-Analytics-and-Digital-Twins-for-Real-Time-3D-Printing\inferece_deployement\stream1.py", line 127, in load_plot_image
    return Image.open(PLOT_PATHS[index])
           ~~~~~~~~~~^^^^^^^^^^^^^^^^^^^
  File "C:\3D_printer\Novel-Cyber-Infrastructure-Enabling-AI-Driven-Analytics-and-Digital-Twins-for-Real-Time-3D-Printing\venv\Lib\site-packages\PIL\Image.py", line 3580, in open
    raise UnidentifiedImageError(msg)
PIL.UnidentifiedImageError: cannot identify image file 'database\\static\\plot3.png'
2025-08-15 11:10:39,351 [ERROR] Error loading plot 3:
Traceback (most recent call last):
  File "C:\3D_printer\Novel-Cyber-Infrastructure-Enabling-AI-Driven-Analytics-and-Digital-Twins-for-Real-Time-3D-Printing\inferece_deployement\stream1.py", line 127, in load_plot_image
    return Image.open(PLOT_PATHS[index])
           ~~~~~~~~~~^^^^^^^^^^^^^^^^^^^
  File "C:\3D_printer\Novel-Cyber-Infrastructure-Enabling-AI-Driven-Analytics-and-Digital-Twins-for-Real-Time-3D-Printing\venv\Lib\site-packages\PIL\Image.py", line 3580, in open
    raise UnidentifiedImageError(msg)
PIL.UnidentifiedImageError: cannot identify image file 'database\\static\\plot3.png'
2025-08-15 11:10:39,472 [ERROR] Error loading plot 3:
Traceback (most recent call last):
  File "C:\3D_printer\Novel-Cyber-Infrastructure-Enabling-AI-Driven-Analytics-and-Digital-Twins-for-Real-Time-3D-Printing\inferece_deployement\stream1.py", line 127, in load_plot_image
    return Image.open(PLOT_PATHS[index])
           ~~~~~~~~~~^^^^^^^^^^^^^^^^^^^
  File "C:\3D_printer\Novel-Cyber-Infrastructure-Enabling-AI-Driven-Analytics-and-Digital-Twins-for-Real-Time-3D-Printing\venv\Lib\site-packages\PIL\Image.py", line 3580, in open
    raise UnidentifiedImageError(msg)
PIL.UnidentifiedImageError: cannot identify image file 'database\\static\\plot3.png'
2025-08-15 11:10:39,895 [ERROR] Error loading plot 3:
Traceback (most recent call last):
  File "C:\3D_printer\Novel-Cyber-Infrastructure-Enabling-AI-Driven-Analytics-and-Digital-Twins-for-Real-Time-3D-Printing\inferece_deployement\stream1.py", line 127, in load_plot_image
    return Image.open(PLOT_PATHS[index])
           ~~~~~~~~~~^^^^^^^^^^^^^^^^^^^
  File "C:\3D_printer\Novel-Cyber-Infrastructure-Enabling-AI-Driven-Analytics-and-Digital-Twins-for-Real-Time-3D-Printing\venv\Lib\site-packages\PIL\Image.py", line 3580, in open
    raise UnidentifiedImageError(msg)
PIL.UnidentifiedImageError: cannot identify image file 'database\\static\\plot3.png'
2025-08-15 11:10:40,944 [ERROR] Error loading plot 3:
Traceback (most recent call last):
  File "C:\3D_printer\Novel-Cyber-Infrastructure-Enabling-AI-Driven-Analytics-and-Digital-Twins-for-Real-Time-3D-Printing\inferece_deployement\stream1.py", line 127, in load_plot_image
    return Image.open(PLOT_PATHS[index])
           ~~~~~~~~~~^^^^^^^^^^^^^^^^^^^
  File "C:\3D_printer\Novel-Cyber-Infrastructure-Enabling-AI-Driven-Analytics-and-Digital-Twins-for-Real-Time-3D-Printing\venv\Lib\site-packages\PIL\Image.py", line 3580, in open
    raise UnidentifiedImageError(msg)
PIL.UnidentifiedImageError: cannot identify image file 'database\\static\\plot3.png'
2025-08-15 11:10:45,492 [ERROR] Error loading plot 3:
Traceback (most recent call last):
  File "C:\3D_printer\Novel-Cyber-Infrastructure-Enabling-AI-Driven-Analytics-and-Digital-Twins-for-Real-Time-3D-Printing\inferece_deployement\stream1.py", line 127, in load_plot_image
    return Image.open(PLOT_PATHS[index])
           ~~~~~~~~~~^^^^^^^^^^^^^^^^^^^
  File "C:\3D_printer\Novel-Cyber-Infrastructure-Enabling-AI-Driven-Analytics-and-Digital-Twins-for-Real-Time-3D-Printing\venv\Lib\site-packages\PIL\Image.py", line 3580, in open
    raise UnidentifiedImageError(msg)
PIL.UnidentifiedImageError: cannot identify image file 'database\\static\\plot3.png'
2025-08-15 11:10:50,035 [ERROR] Error loading plot 3:
Traceback (most recent call last):
  File "C:\3D_printer\Novel-Cyber-Infrastructure-Enabling-AI-Driven-Analytics-and-Digital-Twins-for-Real-Time-3D-Printing\inferece_deployement\stream1.py", line 127, in load_plot_image
    return Image.open(PLOT_PATHS[index])
           ~~~~~~~~~~^^^^^^^^^^^^^^^^^^^
  File "C:\3D_printer\Novel-Cyber-Infrastructure-Enabling-AI-Driven-Analytics-and-Digital-Twins-for-Real-Time-3D-Printing\venv\Lib\site-packages\PIL\Image.py", line 3580, in open
    raise UnidentifiedImageError(msg)
PIL.UnidentifiedImageError: cannot identify image file 'database\\static\\plot3.png'
2025-08-15 11:10:50,802 [ERROR] Error loading plot 3:
Traceback (most recent call last):
  File "C:\3D_printer\Novel-Cyber-Infrastructure-Enabling-AI-Driven-Analytics-and-Digital-Twins-for-Real-Time-3D-Printing\inferece_deployement\stream1.py", line 127, in load_plot_image
    return Image.open(PLOT_PATHS[index])
           ~~~~~~~~~~^^^^^^^^^^^^^^^^^^^
  File "C:\3D_printer\Novel-Cyber-Infrastructure-Enabling-AI-Driven-Analytics-and-Digital-Twins-for-Real-Time-3D-Printing\venv\Lib\site-packages\PIL\Image.py", line 3580, in open
    raise UnidentifiedImageError(msg)
PIL.UnidentifiedImageError: cannot identify image file 'database\\static\\plot3.png'
2025-08-15 11:10:51,194 [ERROR] Error loading plot 3:
Traceback (most recent call last):
  File "C:\3D_printer\Novel-Cyber-Infrastructure-Enabling-AI-Driven-Analytics-and-Digital-Twins-for-Real-Time-3D-Printing\inferece_deployement\stream1.py", line 127, in load_plot_image
    return Image.open(PLOT_PATHS[index])
           ~~~~~~~~~~^^^^^^^^^^^^^^^^^^^
  File "C:\3D_printer\Novel-Cyber-Infrastructure-Enabling-AI-Driven-Analytics-and-Digital-Twins-for-Real-Time-3D-Printing\venv\Lib\site-packages\PIL\Image.py", line 3580, in open
    raise UnidentifiedImageError(msg)
PIL.UnidentifiedImageError: cannot identify image file 'database\\static\\plot3.png'
2025-08-15 11:10:55,402 [ERROR] Error loading plot 2:
Traceback (most recent call last):
  File "C:\3D_printer\Novel-Cyber-Infrastructure-Enabling-AI-Driven-Analytics-and-Digital-Twins-for-Real-Time-3D-Printing\inferece_deployement\stream1.py", line 127, in load_plot_image
    return Image.open(PLOT_PATHS[index])
           ~~~~~~~~~~^^^^^^^^^^^^^^^^^^^
  File "C:\3D_printer\Novel-Cyber-Infrastructure-Enabling-AI-Driven-Analytics-and-Digital-Twins-for-Real-Time-3D-Printing\venv\Lib\site-packages\PIL\Image.py", line 3580, in open
    raise UnidentifiedImageError(msg)
PIL.UnidentifiedImageError: cannot identify image file 'database\\static\\plot2.png'
2025-08-15 11:11:00,822 [ERROR] Error loading plot 3:
Traceback (most recent call last):
  File "C:\3D_printer\Novel-Cyber-Infrastructure-Enabling-AI-Driven-Analytics-and-Digital-Twins-for-Real-Time-3D-Printing\inferece_deployement\stream1.py", line 127, in load_plot_image
    return Image.open(PLOT_PATHS[index])
           ~~~~~~~~~~^^^^^^^^^^^^^^^^^^^
  File "C:\3D_printer\Novel-Cyber-Infrastructure-Enabling-AI-Driven-Analytics-and-Digital-Twins-for-Real-Time-3D-Printing\venv\Lib\site-packages\PIL\Image.py", line 3580, in open
    raise UnidentifiedImageError(msg)
PIL.UnidentifiedImageError: cannot identify image file 'database\\static\\plot3.png'
2025-08-15 11:11:01,993 [ERROR] Error loading plot 3:
Traceback (most recent call last):
  File "C:\3D_printer\Novel-Cyber-Infrastructure-Enabling-AI-Driven-Analytics-and-Digital-Twins-for-Real-Time-3D-Printing\inferece_deployement\stream1.py", line 127, in load_plot_image
    return Image.open(PLOT_PATHS[index])
           ~~~~~~~~~~^^^^^^^^^^^^^^^^^^^
  File "C:\3D_printer\Novel-Cyber-Infrastructure-Enabling-AI-Driven-Analytics-and-Digital-Twins-for-Real-Time-3D-Printing\venv\Lib\site-packages\PIL\Image.py", line 3580, in open
    raise UnidentifiedImageError(msg)
PIL.UnidentifiedImageError: cannot identify image file 'database\\static\\plot3.png'
2025-08-15 11:11:02,407 [ERROR] Error loading plot 3:
Traceback (most recent call last):
  File "C:\3D_printer\Novel-Cyber-Infrastructure-Enabling-AI-Driven-Analytics-and-Digital-Twins-for-Real-Time-3D-Printing\inferece_deployement\stream1.py", line 127, in load_plot_image
    return Image.open(PLOT_PATHS[index])
           ~~~~~~~~~~^^^^^^^^^^^^^^^^^^^
  File "C:\3D_printer\Novel-Cyber-Infrastructure-Enabling-AI-Driven-Analytics-and-Digital-Twins-for-Real-Time-3D-Printing\venv\Lib\site-packages\PIL\Image.py", line 3580, in open
    raise UnidentifiedImageError(msg)
PIL.UnidentifiedImageError: cannot identify image file 'database\\static\\plot3.png'
2025-08-15 11:11:06,342 [ERROR] Error loading plot 3:
Traceback (most recent call last):
  File "C:\3D_printer\Novel-Cyber-Infrastructure-Enabling-AI-Driven-Analytics-and-Digital-Twins-for-Real-Time-3D-Printing\inferece_deployement\stream1.py", line 127, in load_plot_image
    return Image.open(PLOT_PATHS[index])
           ~~~~~~~~~~^^^^^^^^^^^^^^^^^^^
  File "C:\3D_printer\Novel-Cyber-Infrastructure-Enabling-AI-Driven-Analytics-and-Digital-Twins-for-Real-Time-3D-Printing\venv\Lib\site-packages\PIL\Image.py", line 3580, in open
    raise UnidentifiedImageError(msg)
PIL.UnidentifiedImageError: cannot identify image file 'database\\static\\plot3.png'
2025-08-15 11:11:07,481 [ERROR] Error loading plot 3:
Traceback (most recent call last):
  File "C:\3D_printer\Novel-Cyber-Infrastructure-Enabling-AI-Driven-Analytics-and-Digital-Twins-for-Real-Time-3D-Printing\inferece_deployement\stream1.py", line 127, in load_plot_image
    return Image.open(PLOT_PATHS[index])
           ~~~~~~~~~~^^^^^^^^^^^^^^^^^^^
  File "C:\3D_printer\Novel-Cyber-Infrastructure-Enabling-AI-Driven-Analytics-and-Digital-Twins-for-Real-Time-3D-Printing\venv\Lib\site-packages\PIL\Image.py", line 3580, in open
    raise UnidentifiedImageError(msg)
PIL.UnidentifiedImageError: cannot identify image file 'database\\static\\plot3.png'
2025-08-15 12:43:23,710 [ERROR] Error loading plot 3:
Traceback (most recent call last):
  File "C:\3D_printer\Novel-Cyber-Infrastructure-Enabling-AI-Driven-Analytics-and-Digital-Twins-for-Real-Time-3D-Printing\inferece_deployement\stream1.py", line 127, in load_plot_image
    return Image.open(PLOT_PATHS[index])
           ~~~~~~~~~~^^^^^^^^^^^^^^^^^^^
  File "C:\3D_printer\Novel-Cyber-Infrastructure-Enabling-AI-Driven-Analytics-and-Digital-Twins-for-Real-Time-3D-Printing\venv\Lib\site-packages\PIL\Image.py", line 3580, in open
    raise UnidentifiedImageError(msg)
PIL.UnidentifiedImageError: cannot identify image file 'database\\static\\plot3.png'
2025-08-15 12:43:32,500 [INFO] Command 'start' sent. Status: 204
2025-08-15 12:43:37,717 [ERROR] Error loading plot 3:
Traceback (most recent call last):
  File "C:\3D_printer\Novel-Cyber-Infrastructure-Enabling-AI-Driven-Analytics-and-Digital-Twins-for-Real-Time-3D-Printing\inferece_deployement\stream1.py", line 127, in load_plot_image
    return Image.open(PLOT_PATHS[index])
           ~~~~~~~~~~^^^^^^^^^^^^^^^^^^^
  File "C:\3D_printer\Novel-Cyber-Infrastructure-Enabling-AI-Driven-Analytics-and-Digital-Twins-for-Real-Time-3D-Printing\venv\Lib\site-packages\PIL\Image.py", line 3580, in open
    raise UnidentifiedImageError(msg)
PIL.UnidentifiedImageError: cannot identify image file 'database\\static\\plot3.png'
2025-08-15 12:43:58,410 [ERROR] Error loading plot 3:
Traceback (most recent call last):
  File "C:\3D_printer\Novel-Cyber-Infrastructure-Enabling-AI-Driven-Analytics-and-Digital-Twins-for-Real-Time-3D-Printing\inferece_deployement\stream1.py", line 127, in load_plot_image
    return Image.open(PLOT_PATHS[index])
           ~~~~~~~~~~^^^^^^^^^^^^^^^^^^^
  File "C:\3D_printer\Novel-Cyber-Infrastructure-Enabling-AI-Driven-Analytics-and-Digital-Twins-for-Real-Time-3D-Printing\venv\Lib\site-packages\PIL\Image.py", line 3580, in open
    raise UnidentifiedImageError(msg)
PIL.UnidentifiedImageError: cannot identify image file 'database\\static\\plot3.png'
2025-08-15 13:03:16,573 [ERROR] Error loading plot 3:
Traceback (most recent call last):
  File "C:\3D_printer\Novel-Cyber-Infrastructure-Enabling-AI-Driven-Analytics-and-Digital-Twins-for-Real-Time-3D-Printing\inferece_deployement\stream1.py", line 127, in load_plot_image
    return Image.open(PLOT_PATHS[index])
           ~~~~~~~~~~^^^^^^^^^^^^^^^^^^^
  File "C:\3D_printer\Novel-Cyber-Infrastructure-Enabling-AI-Driven-Analytics-and-Digital-Twins-for-Real-Time-3D-Printing\venv\Lib\site-packages\PIL\Image.py", line 3580, in open
    raise UnidentifiedImageError(msg)
PIL.UnidentifiedImageError: cannot identify image file 'database\\static\\plot3.png'
2025-08-15 13:03:16,798 [ERROR] Error loading plot 3:
Traceback (most recent call last):
  File "C:\3D_printer\Novel-Cyber-Infrastructure-Enabling-AI-Driven-Analytics-and-Digital-Twins-for-Real-Time-3D-Printing\inferece_deployement\stream1.py", line 127, in load_plot_image
    return Image.open(PLOT_PATHS[index])
           ~~~~~~~~~~^^^^^^^^^^^^^^^^^^^
  File "C:\3D_printer\Novel-Cyber-Infrastructure-Enabling-AI-Driven-Analytics-and-Digital-Twins-for-Real-Time-3D-Printing\venv\Lib\site-packages\PIL\Image.py", line 3580, in open
    raise UnidentifiedImageError(msg)
PIL.UnidentifiedImageError: cannot identify image file 'database\\static\\plot3.png'
2025-08-15 13:03:33,849 [ERROR] Error loading plot 3:
Traceback (most recent call last):
  File "C:\3D_printer\Novel-Cyber-Infrastructure-Enabling-AI-Driven-Analytics-and-Digital-Twins-for-Real-Time-3D-Printing\inferece_deployement\stream1.py", line 127, in load_plot_image
    return Image.open(PLOT_PATHS[index])
           ~~~~~~~~~~^^^^^^^^^^^^^^^^^^^
  File "C:\3D_printer\Novel-Cyber-Infrastructure-Enabling-AI-Driven-Analytics-and-Digital-Twins-for-Real-Time-3D-Printing\venv\Lib\site-packages\PIL\Image.py", line 3580, in open
    raise UnidentifiedImageError(msg)
PIL.UnidentifiedImageError: cannot identify image file 'database\\static\\plot3.png'
2025-08-15 13:03:39,215 [ERROR] Error loading plot 2:
Traceback (most recent call last):
  File "C:\3D_printer\Novel-Cyber-Infrastructure-Enabling-AI-Driven-Analytics-and-Digital-Twins-for-Real-Time-3D-Printing\inferece_deployement\stream1.py", line 127, in load_plot_image
    return Image.open(PLOT_PATHS[index])
           ~~~~~~~~~~^^^^^^^^^^^^^^^^^^^
  File "C:\3D_printer\Novel-Cyber-Infrastructure-Enabling-AI-Driven-Analytics-and-Digital-Twins-for-Real-Time-3D-Printing\venv\Lib\site-packages\PIL\Image.py", line 3580, in open
    raise UnidentifiedImageError(msg)
PIL.UnidentifiedImageError: cannot identify image file 'database\\static\\plot2.png'
2025-08-15 13:03:39,409 [ERROR] Error loading plot 3:
Traceback (most recent call last):
  File "C:\3D_printer\Novel-Cyber-Infrastructure-Enabling-AI-Driven-Analytics-and-Digital-Twins-for-Real-Time-3D-Printing\inferece_deployement\stream1.py", line 127, in load_plot_image
    return Image.open(PLOT_PATHS[index])
           ~~~~~~~~~~^^^^^^^^^^^^^^^^^^^
  File "C:\3D_printer\Novel-Cyber-Infrastructure-Enabling-AI-Driven-Analytics-and-Digital-Twins-for-Real-Time-3D-Printing\venv\Lib\site-packages\PIL\Image.py", line 3580, in open
    raise UnidentifiedImageError(msg)
PIL.UnidentifiedImageError: cannot identify image file 'database\\static\\plot3.png'
2025-08-15 14:37:15,468 [ERROR] Error loading plot 3:
Traceback (most recent call last):
  File "C:\3D_printer\Novel-Cyber-Infrastructure-Enabling-AI-Driven-Analytics-and-Digital-Twins-for-Real-Time-3D-Printing\inferece_deployement\stream1.py", line 127, in load_plot_image
    return Image.open(PLOT_PATHS[index])
           ~~~~~~~~~~^^^^^^^^^^^^^^^^^^^
  File "C:\3D_printer\Novel-Cyber-Infrastructure-Enabling-AI-Driven-Analytics-and-Digital-Twins-for-Real-Time-3D-Printing\venv\Lib\site-packages\PIL\Image.py", line 3580, in open
    raise UnidentifiedImageError(msg)
PIL.UnidentifiedImageError: cannot identify image file 'database\\static\\plot3.png'
2025-08-15 14:38:46,993 [ERROR] Error loading plot 3:
Traceback (most recent call last):
  File "C:\3D_printer\Novel-Cyber-Infrastructure-Enabling-AI-Driven-Analytics-and-Digital-Twins-for-Real-Time-3D-Printing\inferece_deployement\stream1.py", line 127, in load_plot_image
    return Image.open(PLOT_PATHS[index])
           ~~~~~~~~~~^^^^^^^^^^^^^^^^^^^
  File "C:\3D_printer\Novel-Cyber-Infrastructure-Enabling-AI-Driven-Analytics-and-Digital-Twins-for-Real-Time-3D-Printing\venv\Lib\site-packages\PIL\Image.py", line 3580, in open
    raise UnidentifiedImageError(msg)
PIL.UnidentifiedImageError: cannot identify image file 'database\\static\\plot3.png'
2025-08-15 14:38:52,719 [ERROR] Error loading plot 3:
Traceback (most recent call last):
  File "C:\3D_printer\Novel-Cyber-Infrastructure-Enabling-AI-Driven-Analytics-and-Digital-Twins-for-Real-Time-3D-Printing\inferece_deployement\stream1.py", line 127, in load_plot_image
    return Image.open(PLOT_PATHS[index])
           ~~~~~~~~~~^^^^^^^^^^^^^^^^^^^
  File "C:\3D_printer\Novel-Cyber-Infrastructure-Enabling-AI-Driven-Analytics-and-Digital-Twins-for-Real-Time-3D-Printing\venv\Lib\site-packages\PIL\Image.py", line 3580, in open
    raise UnidentifiedImageError(msg)
PIL.UnidentifiedImageError: cannot identify image file 'database\\static\\plot3.png'
2025-08-15 14:39:17,982 [ERROR] Error loading plot 2:
Traceback (most recent call last):
  File "C:\3D_printer\Novel-Cyber-Infrastructure-Enabling-AI-Driven-Analytics-and-Digital-Twins-for-Real-Time-3D-Printing\inferece_deployement\stream1.py", line 127, in load_plot_image
    return Image.open(PLOT_PATHS[index])
           ~~~~~~~~~~^^^^^^^^^^^^^^^^^^^
  File "C:\3D_printer\Novel-Cyber-Infrastructure-Enabling-AI-Driven-Analytics-and-Digital-Twins-for-Real-Time-3D-Printing\venv\Lib\site-packages\PIL\Image.py", line 3580, in open
    raise UnidentifiedImageError(msg)
PIL.UnidentifiedImageError: cannot identify image file 'database\\static\\plot2.png'
2025-08-15 14:39:17,986 [ERROR] Error loading plot 3:
Traceback (most recent call last):
  File "C:\3D_printer\Novel-Cyber-Infrastructure-Enabling-AI-Driven-Analytics-and-Digital-Twins-for-Real-Time-3D-Printing\inferece_deployement\stream1.py", line 127, in load_plot_image
    return Image.open(PLOT_PATHS[index])
           ~~~~~~~~~~^^^^^^^^^^^^^^^^^^^
  File "C:\3D_printer\Novel-Cyber-Infrastructure-Enabling-AI-Driven-Analytics-and-Digital-Twins-for-Real-Time-3D-Printing\venv\Lib\site-packages\PIL\Image.py", line 3580, in open
    raise UnidentifiedImageError(msg)
PIL.UnidentifiedImageError: cannot identify image file 'database\\static\\plot3.png'
2025-08-15 14:39:23,282 [ERROR] Error loading plot 2:
Traceback (most recent call last):
  File "C:\3D_printer\Novel-Cyber-Infrastructure-Enabling-AI-Driven-Analytics-and-Digital-Twins-for-Real-Time-3D-Printing\inferece_deployement\stream1.py", line 127, in load_plot_image
    return Image.open(PLOT_PATHS[index])
           ~~~~~~~~~~^^^^^^^^^^^^^^^^^^^
  File "C:\3D_printer\Novel-Cyber-Infrastructure-Enabling-AI-Driven-Analytics-and-Digital-Twins-for-Real-Time-3D-Printing\venv\Lib\site-packages\PIL\Image.py", line 3580, in open
    raise UnidentifiedImageError(msg)
PIL.UnidentifiedImageError: cannot identify image file 'database\\static\\plot2.png'
2025-08-15 14:39:34,315 [ERROR] Error loading plot 2:
Traceback (most recent call last):
  File "C:\3D_printer\Novel-Cyber-Infrastructure-Enabling-AI-Driven-Analytics-and-Digital-Twins-for-Real-Time-3D-Printing\inferece_deployement\stream1.py", line 127, in load_plot_image
    return Image.open(PLOT_PATHS[index])
           ~~~~~~~~~~^^^^^^^^^^^^^^^^^^^
  File "C:\3D_printer\Novel-Cyber-Infrastructure-Enabling-AI-Driven-Analytics-and-Digital-Twins-for-Real-Time-3D-Printing\venv\Lib\site-packages\PIL\Image.py", line 3580, in open
    raise UnidentifiedImageError(msg)
PIL.UnidentifiedImageError: cannot identify image file 'database\\static\\plot2.png'
2025-08-15 14:40:13,579 [ERROR] Error loading plot 3:
Traceback (most recent call last):
  File "C:\3D_printer\Novel-Cyber-Infrastructure-Enabling-AI-Driven-Analytics-and-Digital-Twins-for-Real-Time-3D-Printing\inferece_deployement\stream1.py", line 127, in load_plot_image
    return Image.open(PLOT_PATHS[index])
           ~~~~~~~~~~^^^^^^^^^^^^^^^^^^^
  File "C:\3D_printer\Novel-Cyber-Infrastructure-Enabling-AI-Driven-Analytics-and-Digital-Twins-for-Real-Time-3D-Printing\venv\Lib\site-packages\PIL\Image.py", line 3580, in open
    raise UnidentifiedImageError(msg)
PIL.UnidentifiedImageError: cannot identify image file 'database\\static\\plot3.png'
2025-08-15 14:40:19,873 [ERROR] Error loading plot 2:
Traceback (most recent call last):
  File "C:\3D_printer\Novel-Cyber-Infrastructure-Enabling-AI-Driven-Analytics-and-Digital-Twins-for-Real-Time-3D-Printing\inferece_deployement\stream1.py", line 127, in load_plot_image
    return Image.open(PLOT_PATHS[index])
           ~~~~~~~~~~^^^^^^^^^^^^^^^^^^^
  File "C:\3D_printer\Novel-Cyber-Infrastructure-Enabling-AI-Driven-Analytics-and-Digital-Twins-for-Real-Time-3D-Printing\venv\Lib\site-packages\PIL\Image.py", line 3580, in open
    raise UnidentifiedImageError(msg)
PIL.UnidentifiedImageError: cannot identify image file 'database\\static\\plot2.png'
2025-08-15 14:40:19,889 [ERROR] Error loading plot 3:
Traceback (most recent call last):
  File "C:\3D_printer\Novel-Cyber-Infrastructure-Enabling-AI-Driven-Analytics-and-Digital-Twins-for-Real-Time-3D-Printing\inferece_deployement\stream1.py", line 127, in load_plot_image
    return Image.open(PLOT_PATHS[index])
           ~~~~~~~~~~^^^^^^^^^^^^^^^^^^^
  File "C:\3D_printer\Novel-Cyber-Infrastructure-Enabling-AI-Driven-Analytics-and-Digital-Twins-for-Real-Time-3D-Printing\venv\Lib\site-packages\PIL\Image.py", line 3580, in open
    raise UnidentifiedImageError(msg)
PIL.UnidentifiedImageError: cannot identify image file 'database\\static\\plot3.png'
2025-08-15 14:40:25,508 [ERROR] Error loading plot 2:
Traceback (most recent call last):
  File "C:\3D_printer\Novel-Cyber-Infrastructure-Enabling-AI-Driven-Analytics-and-Digital-Twins-for-Real-Time-3D-Printing\inferece_deployement\stream1.py", line 127, in load_plot_image
    return Image.open(PLOT_PATHS[index])
           ~~~~~~~~~~^^^^^^^^^^^^^^^^^^^
  File "C:\3D_printer\Novel-Cyber-Infrastructure-Enabling-AI-Driven-Analytics-and-Digital-Twins-for-Real-Time-3D-Printing\venv\Lib\site-packages\PIL\Image.py", line 3580, in open
    raise UnidentifiedImageError(msg)
PIL.UnidentifiedImageError: cannot identify image file 'database\\static\\plot2.png'
2025-08-15 14:43:21,961 [ERROR] Error loading plot 2:
Traceback (most recent call last):
  File "C:\3D_printer\Novel-Cyber-Infrastructure-Enabling-AI-Driven-Analytics-and-Digital-Twins-for-Real-Time-3D-Printing\inferece_deployement\stream1.py", line 127, in load_plot_image
    return Image.open(PLOT_PATHS[index])
           ~~~~~~~~~~^^^^^^^^^^^^^^^^^^^
  File "C:\3D_printer\Novel-Cyber-Infrastructure-Enabling-AI-Driven-Analytics-and-Digital-Twins-for-Real-Time-3D-Printing\venv\Lib\site-packages\PIL\Image.py", line 3580, in open
    raise UnidentifiedImageError(msg)
PIL.UnidentifiedImageError: cannot identify image file 'database\\static\\plot2.png'
2025-08-15 14:43:33,691 [ERROR] Error loading plot 3:
Traceback (most recent call last):
  File "C:\3D_printer\Novel-Cyber-Infrastructure-Enabling-AI-Driven-Analytics-and-Digital-Twins-for-Real-Time-3D-Printing\inferece_deployement\stream1.py", line 127, in load_plot_image
    return Image.open(PLOT_PATHS[index])
           ~~~~~~~~~~^^^^^^^^^^^^^^^^^^^
  File "C:\3D_printer\Novel-Cyber-Infrastructure-Enabling-AI-Driven-Analytics-and-Digital-Twins-for-Real-Time-3D-Printing\venv\Lib\site-packages\PIL\Image.py", line 3580, in open
    raise UnidentifiedImageError(msg)
PIL.UnidentifiedImageError: cannot identify image file 'database\\static\\plot3.png'
2025-08-15 14:43:39,265 [ERROR] Error loading plot 3:
Traceback (most recent call last):
  File "C:\3D_printer\Novel-Cyber-Infrastructure-Enabling-AI-Driven-Analytics-and-Digital-Twins-for-Real-Time-3D-Printing\inferece_deployement\stream1.py", line 127, in load_plot_image
    return Image.open(PLOT_PATHS[index])
           ~~~~~~~~~~^^^^^^^^^^^^^^^^^^^
  File "C:\3D_printer\Novel-Cyber-Infrastructure-Enabling-AI-Driven-Analytics-and-Digital-Twins-for-Real-Time-3D-Printing\venv\Lib\site-packages\PIL\Image.py", line 3580, in open
    raise UnidentifiedImageError(msg)
PIL.UnidentifiedImageError: cannot identify image file 'database\\static\\plot3.png'
2025-08-15 14:43:46,024 [ERROR] Error loading plot 2:
Traceback (most recent call last):
  File "C:\3D_printer\Novel-Cyber-Infrastructure-Enabling-AI-Driven-Analytics-and-Digital-Twins-for-Real-Time-3D-Printing\inferece_deployement\stream1.py", line 127, in load_plot_image
    return Image.open(PLOT_PATHS[index])
           ~~~~~~~~~~^^^^^^^^^^^^^^^^^^^
  File "C:\3D_printer\Novel-Cyber-Infrastructure-Enabling-AI-Driven-Analytics-and-Digital-Twins-for-Real-Time-3D-Printing\venv\Lib\site-packages\PIL\Image.py", line 3580, in open
    raise UnidentifiedImageError(msg)
PIL.UnidentifiedImageError: cannot identify image file 'database\\static\\plot2.png'
2025-08-15 14:43:51,812 [ERROR] Error loading plot 2:
Traceback (most recent call last):
  File "C:\3D_printer\Novel-Cyber-Infrastructure-Enabling-AI-Driven-Analytics-and-Digital-Twins-for-Real-Time-3D-Printing\inferece_deployement\stream1.py", line 127, in load_plot_image
    return Image.open(PLOT_PATHS[index])
           ~~~~~~~~~~^^^^^^^^^^^^^^^^^^^
  File "C:\3D_printer\Novel-Cyber-Infrastructure-Enabling-AI-Driven-Analytics-and-Digital-Twins-for-Real-Time-3D-Printing\venv\Lib\site-packages\PIL\Image.py", line 3580, in open
    raise UnidentifiedImageError(msg)
PIL.UnidentifiedImageError: cannot identify image file 'database\\static\\plot2.png'
2025-08-15 14:43:51,830 [ERROR] Error loading plot 3:
Traceback (most recent call last):
  File "C:\3D_printer\Novel-Cyber-Infrastructure-Enabling-AI-Driven-Analytics-and-Digital-Twins-for-Real-Time-3D-Printing\inferece_deployement\stream1.py", line 127, in load_plot_image
    return Image.open(PLOT_PATHS[index])
           ~~~~~~~~~~^^^^^^^^^^^^^^^^^^^
  File "C:\3D_printer\Novel-Cyber-Infrastructure-Enabling-AI-Driven-Analytics-and-Digital-Twins-for-Real-Time-3D-Printing\venv\Lib\site-packages\PIL\Image.py", line 3580, in open
    raise UnidentifiedImageError(msg)
PIL.UnidentifiedImageError: cannot identify image file 'database\\static\\plot3.png'
2025-08-15 14:43:57,314 [ERROR] Error loading plot 2:
Traceback (most recent call last):
  File "C:\3D_printer\Novel-Cyber-Infrastructure-Enabling-AI-Driven-Analytics-and-Digital-Twins-for-Real-Time-3D-Printing\inferece_deployement\stream1.py", line 127, in load_plot_image
    return Image.open(PLOT_PATHS[index])
           ~~~~~~~~~~^^^^^^^^^^^^^^^^^^^
  File "C:\3D_printer\Novel-Cyber-Infrastructure-Enabling-AI-Driven-Analytics-and-Digital-Twins-for-Real-Time-3D-Printing\venv\Lib\site-packages\PIL\Image.py", line 3580, in open
    raise UnidentifiedImageError(msg)
PIL.UnidentifiedImageError: cannot identify image file 'database\\static\\plot2.png'
2025-08-15 14:43:57,318 [ERROR] Error loading plot 3:
Traceback (most recent call last):
  File "C:\3D_printer\Novel-Cyber-Infrastructure-Enabling-AI-Driven-Analytics-and-Digital-Twins-for-Real-Time-3D-Printing\inferece_deployement\stream1.py", line 127, in load_plot_image
    return Image.open(PLOT_PATHS[index])
           ~~~~~~~~~~^^^^^^^^^^^^^^^^^^^
  File "C:\3D_printer\Novel-Cyber-Infrastructure-Enabling-AI-Driven-Analytics-and-Digital-Twins-for-Real-Time-3D-Printing\venv\Lib\site-packages\PIL\Image.py", line 3580, in open
    raise UnidentifiedImageError(msg)
PIL.UnidentifiedImageError: cannot identify image file 'database\\static\\plot3.png'
2025-08-15 14:43:59,465 [ERROR] Error loading plot 2:
Traceback (most recent call last):
  File "C:\3D_printer\Novel-Cyber-Infrastructure-Enabling-AI-Driven-Analytics-and-Digital-Twins-for-Real-Time-3D-Printing\inferece_deployement\stream1.py", line 127, in load_plot_image
    return Image.open(PLOT_PATHS[index])
           ~~~~~~~~~~^^^^^^^^^^^^^^^^^^^
  File "C:\3D_printer\Novel-Cyber-Infrastructure-Enabling-AI-Driven-Analytics-and-Digital-Twins-for-Real-Time-3D-Printing\venv\Lib\site-packages\PIL\Image.py", line 3580, in open
    raise UnidentifiedImageError(msg)
PIL.UnidentifiedImageError: cannot identify image file 'database\\static\\plot2.png'
2025-08-15 14:44:05,511 [ERROR] Error loading plot 3:
Traceback (most recent call last):
  File "C:\3D_printer\Novel-Cyber-Infrastructure-Enabling-AI-Driven-Analytics-and-Digital-Twins-for-Real-Time-3D-Printing\inferece_deployement\stream1.py", line 127, in load_plot_image
    return Image.open(PLOT_PATHS[index])
           ~~~~~~~~~~^^^^^^^^^^^^^^^^^^^
  File "C:\3D_printer\Novel-Cyber-Infrastructure-Enabling-AI-Driven-Analytics-and-Digital-Twins-for-Real-Time-3D-Printing\venv\Lib\site-packages\PIL\Image.py", line 3580, in open
    raise UnidentifiedImageError(msg)
PIL.UnidentifiedImageError: cannot identify image file 'database\\static\\plot3.png'
2025-08-18 14:02:11,748 [INFO] Command 'start' sent. Status: 204
2025-08-18 14:08:04,942 [INFO] Command 'pause' sent. Status: 204
2025-08-18 14:08:40,960 [INFO] Command 'pause' sent. Status: 204
